2019-09-16 14:13:55.3037 ERROR Something went wrong: System.NullReferenceException: Object reference not set to an instance of an object.
   at ElMaitre.Web3.Controllers.LawyerController.<PayWithCard>d__24.MoveNext() in F:\Freelance\Mohamy\ElMaitre.Web3\Controllers\LawyerController.cs:line 357
--- End of stack trace from previous location where exception was thrown ---
   at System.Runtime.ExceptionServices.ExceptionDispatchInfo.Throw()
   at System.Runtime.CompilerServices.TaskAwaiter.HandleNonSuccessAndDebuggerNotification(Task task)
   at System.Runtime.CompilerServices.TaskAwaiter`1.GetResult()
   at Microsoft.AspNetCore.Mvc.Internal.ControllerActionInvoker.<InvokeActionMethodAsync>d__12.MoveNext()
--- End of stack trace from previous location where exception was thrown ---
   at System.Runtime.ExceptionServices.ExceptionDispatchInfo.Throw()
   at System.Runtime.CompilerServices.TaskAwaiter.HandleNonSuccessAndDebuggerNotification(Task task)
   at Microsoft.AspNetCore.Mvc.Internal.ControllerActionInvoker.<InvokeNextActionFilterAsync>d__10.MoveNext()
--- End of stack trace from previous location where exception was thrown ---
   at System.Runtime.ExceptionServices.ExceptionDispatchInfo.Throw()
   at Microsoft.AspNetCore.Mvc.Internal.ControllerActionInvoker.Rethrow(ActionExecutedContext context)
   at Microsoft.AspNetCore.Mvc.Internal.ControllerActionInvoker.Next(State& next, Scope& scope, Object& state, Boolean& isCompleted)
   at Microsoft.AspNetCore.Mvc.Internal.ControllerActionInvoker.<InvokeInnerFilterAsync>d__14.MoveNext()
--- End of stack trace from previous location where exception was thrown ---
   at System.Runtime.ExceptionServices.ExceptionDispatchInfo.Throw()
   at System.Runtime.CompilerServices.TaskAwaiter.HandleNonSuccessAndDebuggerNotification(Task task)
   at Microsoft.AspNetCore.Mvc.Internal.ResourceInvoker.<InvokeNextResourceFilter>d__22.MoveNext()
--- End of stack trace from previous location where exception was thrown ---
   at System.Runtime.ExceptionServices.ExceptionDispatchInfo.Throw()
   at Microsoft.AspNetCore.Mvc.Internal.ResourceInvoker.Rethrow(ResourceExecutedContext context)
   at Microsoft.AspNetCore.Mvc.Internal.ResourceInvoker.Next(State& next, Scope& scope, Object& state, Boolean& isCompleted)
   at Microsoft.AspNetCore.Mvc.Internal.ResourceInvoker.<InvokeFilterPipelineAsync>d__17.MoveNext()
--- End of stack trace from previous location where exception was thrown ---
   at System.Runtime.ExceptionServices.ExceptionDispatchInfo.Throw()
   at System.Runtime.CompilerServices.TaskAwaiter.HandleNonSuccessAndDebuggerNotification(Task task)
   at Microsoft.AspNetCore.Mvc.Internal.ResourceInvoker.<InvokeAsync>d__15.MoveNext()
--- End of stack trace from previous location where exception was thrown ---
   at System.Runtime.ExceptionServices.ExceptionDispatchInfo.Throw()
   at System.Runtime.CompilerServices.TaskAwaiter.HandleNonSuccessAndDebuggerNotification(Task task)
   at Microsoft.AspNetCore.Builder.RouterMiddleware.<Invoke>d__4.MoveNext()
--- End of stack trace from previous location where exception was thrown ---
   at System.Runtime.ExceptionServices.ExceptionDispatchInfo.Throw()
   at System.Runtime.CompilerServices.TaskAwaiter.HandleNonSuccessAndDebuggerNotification(Task task)
   at Microsoft.AspNetCore.Diagnostics.ExceptionHandlerMiddleware.<Invoke>d__6.MoveNext()
2019-09-16 14:24:58.1640 ERROR Something went wrong: System.InvalidOperationException: Cannot return null from an action method with a return type of 'Microsoft.AspNetCore.Mvc.IActionResult'.
   at Microsoft.AspNetCore.Mvc.Internal.ControllerActionInvoker.<InvokeActionMethodAsync>d__12.MoveNext()
--- End of stack trace from previous location where exception was thrown ---
   at System.Runtime.ExceptionServices.ExceptionDispatchInfo.Throw()
   at System.Runtime.CompilerServices.TaskAwaiter.HandleNonSuccessAndDebuggerNotification(Task task)
   at Microsoft.AspNetCore.Mvc.Internal.ControllerActionInvoker.<InvokeNextActionFilterAsync>d__10.MoveNext()
--- End of stack trace from previous location where exception was thrown ---
   at System.Runtime.ExceptionServices.ExceptionDispatchInfo.Throw()
   at Microsoft.AspNetCore.Mvc.Internal.ControllerActionInvoker.Rethrow(ActionExecutedContext context)
   at Microsoft.AspNetCore.Mvc.Internal.ControllerActionInvoker.Next(State& next, Scope& scope, Object& state, Boolean& isCompleted)
   at Microsoft.AspNetCore.Mvc.Internal.ControllerActionInvoker.<InvokeInnerFilterAsync>d__14.MoveNext()
--- End of stack trace from previous location where exception was thrown ---
   at System.Runtime.ExceptionServices.ExceptionDispatchInfo.Throw()
   at System.Runtime.CompilerServices.TaskAwaiter.HandleNonSuccessAndDebuggerNotification(Task task)
   at Microsoft.AspNetCore.Mvc.Internal.ResourceInvoker.<InvokeNextResourceFilter>d__22.MoveNext()
--- End of stack trace from previous location where exception was thrown ---
   at System.Runtime.ExceptionServices.ExceptionDispatchInfo.Throw()
   at Microsoft.AspNetCore.Mvc.Internal.ResourceInvoker.Rethrow(ResourceExecutedContext context)
   at Microsoft.AspNetCore.Mvc.Internal.ResourceInvoker.Next(State& next, Scope& scope, Object& state, Boolean& isCompleted)
   at Microsoft.AspNetCore.Mvc.Internal.ResourceInvoker.<InvokeFilterPipelineAsync>d__17.MoveNext()
--- End of stack trace from previous location where exception was thrown ---
   at System.Runtime.ExceptionServices.ExceptionDispatchInfo.Throw()
   at System.Runtime.CompilerServices.TaskAwaiter.HandleNonSuccessAndDebuggerNotification(Task task)
   at Microsoft.AspNetCore.Mvc.Internal.ResourceInvoker.<InvokeAsync>d__15.MoveNext()
--- End of stack trace from previous location where exception was thrown ---
   at System.Runtime.ExceptionServices.ExceptionDispatchInfo.Throw()
   at System.Runtime.CompilerServices.TaskAwaiter.HandleNonSuccessAndDebuggerNotification(Task task)
   at Microsoft.AspNetCore.Builder.RouterMiddleware.<Invoke>d__4.MoveNext()
--- End of stack trace from previous location where exception was thrown ---
   at System.Runtime.ExceptionServices.ExceptionDispatchInfo.Throw()
   at System.Runtime.CompilerServices.TaskAwaiter.HandleNonSuccessAndDebuggerNotification(Task task)
   at Microsoft.AspNetCore.Diagnostics.ExceptionHandlerMiddleware.<Invoke>d__6.MoveNext()
2019-09-16 15:47:25.3923 ERROR Something went wrong: System.NullReferenceException: Object reference not set to an instance of an object.
   at ElMaitre.Web3.Controllers.LawyerController.<PayWithCard>d__24.MoveNext() in F:\Freelance\Mohamy\ElMaitre.Web3\Controllers\LawyerController.cs:line 357
--- End of stack trace from previous location where exception was thrown ---
   at System.Runtime.ExceptionServices.ExceptionDispatchInfo.Throw()
   at System.Runtime.CompilerServices.TaskAwaiter.HandleNonSuccessAndDebuggerNotification(Task task)
   at System.Runtime.CompilerServices.TaskAwaiter`1.GetResult()
   at Microsoft.AspNetCore.Mvc.Internal.ControllerActionInvoker.<InvokeActionMethodAsync>d__12.MoveNext()
--- End of stack trace from previous location where exception was thrown ---
   at System.Runtime.ExceptionServices.ExceptionDispatchInfo.Throw()
   at System.Runtime.CompilerServices.TaskAwaiter.HandleNonSuccessAndDebuggerNotification(Task task)
   at Microsoft.AspNetCore.Mvc.Internal.ControllerActionInvoker.<InvokeNextActionFilterAsync>d__10.MoveNext()
--- End of stack trace from previous location where exception was thrown ---
   at System.Runtime.ExceptionServices.ExceptionDispatchInfo.Throw()
   at Microsoft.AspNetCore.Mvc.Internal.ControllerActionInvoker.Rethrow(ActionExecutedContext context)
   at Microsoft.AspNetCore.Mvc.Internal.ControllerActionInvoker.Next(State& next, Scope& scope, Object& state, Boolean& isCompleted)
   at Microsoft.AspNetCore.Mvc.Internal.ControllerActionInvoker.<InvokeInnerFilterAsync>d__14.MoveNext()
--- End of stack trace from previous location where exception was thrown ---
   at System.Runtime.ExceptionServices.ExceptionDispatchInfo.Throw()
   at System.Runtime.CompilerServices.TaskAwaiter.HandleNonSuccessAndDebuggerNotification(Task task)
   at Microsoft.AspNetCore.Mvc.Internal.ResourceInvoker.<InvokeNextResourceFilter>d__22.MoveNext()
--- End of stack trace from previous location where exception was thrown ---
   at System.Runtime.ExceptionServices.ExceptionDispatchInfo.Throw()
   at Microsoft.AspNetCore.Mvc.Internal.ResourceInvoker.Rethrow(ResourceExecutedContext context)
   at Microsoft.AspNetCore.Mvc.Internal.ResourceInvoker.Next(State& next, Scope& scope, Object& state, Boolean& isCompleted)
   at Microsoft.AspNetCore.Mvc.Internal.ResourceInvoker.<InvokeFilterPipelineAsync>d__17.MoveNext()
--- End of stack trace from previous location where exception was thrown ---
   at System.Runtime.ExceptionServices.ExceptionDispatchInfo.Throw()
   at System.Runtime.CompilerServices.TaskAwaiter.HandleNonSuccessAndDebuggerNotification(Task task)
   at Microsoft.AspNetCore.Mvc.Internal.ResourceInvoker.<InvokeAsync>d__15.MoveNext()
--- End of stack trace from previous location where exception was thrown ---
   at System.Runtime.ExceptionServices.ExceptionDispatchInfo.Throw()
   at System.Runtime.CompilerServices.TaskAwaiter.HandleNonSuccessAndDebuggerNotification(Task task)
   at Microsoft.AspNetCore.Builder.RouterMiddleware.<Invoke>d__4.MoveNext()
--- End of stack trace from previous location where exception was thrown ---
   at System.Runtime.ExceptionServices.ExceptionDispatchInfo.Throw()
   at System.Runtime.CompilerServices.TaskAwaiter.HandleNonSuccessAndDebuggerNotification(Task task)
   at Microsoft.AspNetCore.Diagnostics.ExceptionHandlerMiddleware.<Invoke>d__6.MoveNext()
2019-09-16 19:20:17.7106 ERROR Something went wrong: System.InvalidOperationException: Nullable object must have a value.
   at System.ThrowHelper.ThrowInvalidOperationException(ExceptionResource resource)
   at System.Nullable`1.get_Value()
   at ElMaitre.Web.Controllers.AuthController.<Logout>d__10.MoveNext() in F:\Freelance\Mohamy\ElMaitre.Web3\Controllers\AuthController.cs:line 378
--- End of stack trace from previous location where exception was thrown ---
   at System.Runtime.ExceptionServices.ExceptionDispatchInfo.Throw()
   at System.Runtime.CompilerServices.TaskAwaiter.HandleNonSuccessAndDebuggerNotification(Task task)
   at System.Runtime.CompilerServices.TaskAwaiter`1.GetResult()
   at Microsoft.AspNetCore.Mvc.Internal.ControllerActionInvoker.<InvokeActionMethodAsync>d__12.MoveNext()
--- End of stack trace from previous location where exception was thrown ---
   at System.Runtime.ExceptionServices.ExceptionDispatchInfo.Throw()
   at System.Runtime.CompilerServices.TaskAwaiter.HandleNonSuccessAndDebuggerNotification(Task task)
   at Microsoft.AspNetCore.Mvc.Internal.ControllerActionInvoker.<InvokeNextActionFilterAsync>d__10.MoveNext()
--- End of stack trace from previous location where exception was thrown ---
   at System.Runtime.ExceptionServices.ExceptionDispatchInfo.Throw()
   at Microsoft.AspNetCore.Mvc.Internal.ControllerActionInvoker.Rethrow(ActionExecutedContext context)
   at Microsoft.AspNetCore.Mvc.Internal.ControllerActionInvoker.Next(State& next, Scope& scope, Object& state, Boolean& isCompleted)
   at Microsoft.AspNetCore.Mvc.Internal.ControllerActionInvoker.<InvokeInnerFilterAsync>d__14.MoveNext()
--- End of stack trace from previous location where exception was thrown ---
   at System.Runtime.ExceptionServices.ExceptionDispatchInfo.Throw()
   at System.Runtime.CompilerServices.TaskAwaiter.HandleNonSuccessAndDebuggerNotification(Task task)
   at Microsoft.AspNetCore.Mvc.Internal.ResourceInvoker.<InvokeNextResourceFilter>d__22.MoveNext()
--- End of stack trace from previous location where exception was thrown ---
   at System.Runtime.ExceptionServices.ExceptionDispatchInfo.Throw()
   at Microsoft.AspNetCore.Mvc.Internal.ResourceInvoker.Rethrow(ResourceExecutedContext context)
   at Microsoft.AspNetCore.Mvc.Internal.ResourceInvoker.Next(State& next, Scope& scope, Object& state, Boolean& isCompleted)
   at Microsoft.AspNetCore.Mvc.Internal.ResourceInvoker.<InvokeFilterPipelineAsync>d__17.MoveNext()
--- End of stack trace from previous location where exception was thrown ---
   at System.Runtime.ExceptionServices.ExceptionDispatchInfo.Throw()
   at System.Runtime.CompilerServices.TaskAwaiter.HandleNonSuccessAndDebuggerNotification(Task task)
   at Microsoft.AspNetCore.Mvc.Internal.ResourceInvoker.<InvokeAsync>d__15.MoveNext()
--- End of stack trace from previous location where exception was thrown ---
   at System.Runtime.ExceptionServices.ExceptionDispatchInfo.Throw()
   at System.Runtime.CompilerServices.TaskAwaiter.HandleNonSuccessAndDebuggerNotification(Task task)
   at Microsoft.AspNetCore.Builder.RouterMiddleware.<Invoke>d__4.MoveNext()
--- End of stack trace from previous location where exception was thrown ---
   at System.Runtime.ExceptionServices.ExceptionDispatchInfo.Throw()
   at System.Runtime.CompilerServices.TaskAwaiter.HandleNonSuccessAndDebuggerNotification(Task task)
   at Microsoft.AspNetCore.Diagnostics.ExceptionHandlerMiddleware.<Invoke>d__6.MoveNext()
2019-09-16 19:20:35.7016 INFO Failed to send the mail
2019-09-16 19:20:35.7697 ERROR System.Net.Mail.SmtpException: Transaction failed. The server response was: 5.7.1 <unknown[41.235.69.61]>: Client host rejected: Access denied
   at System.Net.Mail.RecipientCommand.CheckResponse(SmtpStatusCode statusCode, String response)
   at System.Net.Mail.RecipientCommand.EndSend(IAsyncResult result, String& response)
   at System.Net.Mail.SendMailAsyncResult.SendToCollectionCompleted(IAsyncResult result)
--- End of stack trace from previous location where exception was thrown ---
   at System.Runtime.ExceptionServices.ExceptionDispatchInfo.Throw()
   at System.Net.Mail.SendMailAsyncResult.End(IAsyncResult result)
   at System.Net.Mail.SmtpClient.SendMailCallback(IAsyncResult result)
--- End of stack trace from previous location where exception was thrown ---
   at System.Runtime.ExceptionServices.ExceptionDispatchInfo.Throw()
   at System.Runtime.CompilerServices.TaskAwaiter.HandleNonSuccessAndDebuggerNotification(Task task)
   at ElMaitre.Web.Helpers.EmailSender.<Send>d__2.MoveNext() in F:\Freelance\Mohamy\ElMaitre.Web3\Helpers\EmailSender.cs:line 63
2019-09-16 19:22:41.3820 INFO Failed to send the mail
2019-09-16 19:22:41.4606 ERROR System.Net.Mail.SmtpException: Transaction failed. The server response was: 5.7.1 <unknown[41.235.69.61]>: Client host rejected: Access denied
   at System.Net.Mail.RecipientCommand.CheckResponse(SmtpStatusCode statusCode, String response)
   at System.Net.Mail.RecipientCommand.EndSend(IAsyncResult result, String& response)
   at System.Net.Mail.SendMailAsyncResult.SendToCollectionCompleted(IAsyncResult result)
--- End of stack trace from previous location where exception was thrown ---
   at System.Runtime.ExceptionServices.ExceptionDispatchInfo.Throw()
   at System.Net.Mail.SendMailAsyncResult.End(IAsyncResult result)
   at System.Net.Mail.SmtpClient.SendMailCallback(IAsyncResult result)
--- End of stack trace from previous location where exception was thrown ---
   at System.Runtime.ExceptionServices.ExceptionDispatchInfo.Throw()
   at System.Runtime.CompilerServices.TaskAwaiter.HandleNonSuccessAndDebuggerNotification(Task task)
   at ElMaitre.Web.Helpers.EmailSender.<Send>d__2.MoveNext()
2019-09-16 19:23:27.1606 INFO Failed to send the mail
2019-09-16 19:23:27.1708 ERROR System.Net.Mail.SmtpException: Transaction failed. The server response was: 5.7.1 <unknown[41.235.69.61]>: Client host rejected: Access denied
   at System.Net.Mail.RecipientCommand.CheckResponse(SmtpStatusCode statusCode, String response)
   at System.Net.Mail.RecipientCommand.EndSend(IAsyncResult result, String& response)
   at System.Net.Mail.SendMailAsyncResult.SendToCollectionCompleted(IAsyncResult result)
--- End of stack trace from previous location where exception was thrown ---
   at System.Runtime.ExceptionServices.ExceptionDispatchInfo.Throw()
   at System.Net.Mail.SendMailAsyncResult.End(IAsyncResult result)
   at System.Net.Mail.SmtpClient.SendMailCallback(IAsyncResult result)
--- End of stack trace from previous location where exception was thrown ---
   at System.Runtime.ExceptionServices.ExceptionDispatchInfo.Throw()
   at System.Runtime.CompilerServices.TaskAwaiter.HandleNonSuccessAndDebuggerNotification(Task task)
   at ElMaitre.Web.Helpers.EmailSender.<Send>d__2.MoveNext()
2019-09-16 19:23:44.5879 INFO Failed to send the mail
2019-09-16 19:23:44.6001 ERROR System.Net.Mail.SmtpException: Transaction failed. The server response was: 5.7.1 <unknown[41.235.69.61]>: Client host rejected: Access denied
   at System.Net.Mail.RecipientCommand.CheckResponse(SmtpStatusCode statusCode, String response)
   at System.Net.Mail.RecipientCommand.EndSend(IAsyncResult result, String& response)
   at System.Net.Mail.SendMailAsyncResult.SendToCollectionCompleted(IAsyncResult result)
--- End of stack trace from previous location where exception was thrown ---
   at System.Runtime.ExceptionServices.ExceptionDispatchInfo.Throw()
   at System.Net.Mail.SendMailAsyncResult.End(IAsyncResult result)
   at System.Net.Mail.SmtpClient.SendMailCallback(IAsyncResult result)
--- End of stack trace from previous location where exception was thrown ---
   at System.Runtime.ExceptionServices.ExceptionDispatchInfo.Throw()
   at System.Runtime.CompilerServices.TaskAwaiter.HandleNonSuccessAndDebuggerNotification(Task task)
   at ElMaitre.Web.Helpers.EmailSender.<Send>d__2.MoveNext()
2019-09-16 19:25:32.3461 INFO Failed to send the mail
2019-09-16 19:25:32.3760 ERROR System.Net.Mail.SmtpException: Transaction failed. The server response was: 5.7.1 <unknown[41.235.69.61]>: Client host rejected: Access denied
   at System.Net.Mail.RecipientCommand.CheckResponse(SmtpStatusCode statusCode, String response)
   at System.Net.Mail.RecipientCommand.EndSend(IAsyncResult result, String& response)
   at System.Net.Mail.SendMailAsyncResult.SendToCollectionCompleted(IAsyncResult result)
--- End of stack trace from previous location where exception was thrown ---
   at System.Runtime.ExceptionServices.ExceptionDispatchInfo.Throw()
   at System.Net.Mail.SendMailAsyncResult.End(IAsyncResult result)
   at System.Net.Mail.SmtpClient.SendMailCallback(IAsyncResult result)
--- End of stack trace from previous location where exception was thrown ---
   at System.Runtime.ExceptionServices.ExceptionDispatchInfo.Throw()
   at System.Runtime.CompilerServices.TaskAwaiter.HandleNonSuccessAndDebuggerNotification(Task task)
   at ElMaitre.Web.Helpers.EmailSender.<Send>d__2.MoveNext()
2019-09-16 19:29:11.3541 INFO Failed to send the mail
2019-09-16 19:29:11.3828 ERROR System.Net.Mail.SmtpException: The SMTP server requires a secure connection or the client was not authenticated. The server response was: 5.7.57 SMTP; Client was not authenticated to send anonymous mail during MAIL FROM [MR2P264CA0053.FRAP264.PROD.OUTLOOK.COM]
   at System.Net.Mail.MailCommand.CheckResponse(SmtpStatusCode statusCode, String response)
   at System.Net.Mail.MailCommand.EndSend(IAsyncResult result)
   at System.Net.Mail.SendMailAsyncResult.SendMailFromCompleted(IAsyncResult result)
--- End of stack trace from previous location where exception was thrown ---
   at System.Runtime.ExceptionServices.ExceptionDispatchInfo.Throw()
   at System.Net.Mail.SendMailAsyncResult.End(IAsyncResult result)
   at System.Net.Mail.SmtpClient.SendMailCallback(IAsyncResult result)
--- End of stack trace from previous location where exception was thrown ---
   at System.Runtime.ExceptionServices.ExceptionDispatchInfo.Throw()
   at System.Runtime.CompilerServices.TaskAwaiter.HandleNonSuccessAndDebuggerNotification(Task task)
   at ElMaitre.Web.Helpers.EmailSender.<Send>d__2.MoveNext()
2019-09-16 19:29:57.1039 INFO Failed to send the mail
2019-09-16 19:29:57.1512 ERROR System.Net.Mail.SmtpException: Transaction failed. The server response was: 5.7.1 <unknown[41.235.69.61]>: Client host rejected: Access denied
   at System.Net.Mail.RecipientCommand.CheckResponse(SmtpStatusCode statusCode, String response)
   at System.Net.Mail.RecipientCommand.EndSend(IAsyncResult result, String& response)
   at System.Net.Mail.SendMailAsyncResult.SendToCollectionCompleted(IAsyncResult result)
--- End of stack trace from previous location where exception was thrown ---
   at System.Runtime.ExceptionServices.ExceptionDispatchInfo.Throw()
   at System.Net.Mail.SendMailAsyncResult.End(IAsyncResult result)
   at System.Net.Mail.SmtpClient.SendMailCallback(IAsyncResult result)
--- End of stack trace from previous location where exception was thrown ---
   at System.Runtime.ExceptionServices.ExceptionDispatchInfo.Throw()
   at System.Runtime.CompilerServices.TaskAwaiter.HandleNonSuccessAndDebuggerNotification(Task task)
   at ElMaitre.Web.Helpers.EmailSender.<Send>d__2.MoveNext()
2019-09-16 19:30:37.3148 INFO Failed to send the mail
2019-09-16 19:30:37.3353 ERROR System.Net.Mail.SmtpException: Failure sending mail. ---> System.Net.Internals.SocketExceptionFactory+ExtendedSocketException: A connection attempt failed because the connected party did not properly respond after a period of time, or established connection failed because connected host has failed to respond 17.56.136.170:465
   at System.Runtime.ExceptionServices.ExceptionDispatchInfo.Throw()
   at System.Net.Sockets.Socket.EndConnect(IAsyncResult asyncResult)
   at System.Net.Sockets.Socket.DoMultipleAddressConnectCallback(Object result, MultipleAddressConnectAsyncResult context)
--- End of stack trace from previous location where exception was thrown ---
   at System.Runtime.ExceptionServices.ExceptionDispatchInfo.Throw()
   at System.Net.Sockets.Socket.DoMultipleAddressConnectCallback(Object result, MultipleAddressConnectAsyncResult context)
   at System.Net.Sockets.Socket.MultipleAddressConnectCallback(IAsyncResult result)
--- End of stack trace from previous location where exception was thrown ---
   at System.Runtime.ExceptionServices.ExceptionDispatchInfo.Throw()
   at System.Net.Sockets.Socket.EndConnect(IAsyncResult asyncResult)
   at System.Net.Sockets.TcpClient.EndConnect(IAsyncResult asyncResult)
   at System.Net.Mail.SmtpConnection.ConnectAndHandshakeAsyncResult.InitializeConnectionCallback(IAsyncResult result)
--- End of stack trace from previous location where exception was thrown ---
   at System.Runtime.ExceptionServices.ExceptionDispatchInfo.Throw()
   at System.Net.Mail.SmtpConnection.ConnectAndHandshakeAsyncResult.End(IAsyncResult result)
   at System.Net.Mail.SmtpTransport.EndGetConnection(IAsyncResult result)
   at System.Net.Mail.SmtpClient.ConnectCallback(IAsyncResult result)
   --- End of inner exception stack trace ---
   at System.Runtime.ExceptionServices.ExceptionDispatchInfo.Throw()
   at System.Runtime.CompilerServices.TaskAwaiter.HandleNonSuccessAndDebuggerNotification(Task task)
   at ElMaitre.Web.Helpers.EmailSender.<Send>d__2.MoveNext()
2019-09-16 19:32:06.6142 INFO Failed to send the mail
2019-09-16 19:32:06.6342 ERROR System.Net.Mail.SmtpException: Failure sending mail. ---> System.Net.Internals.SocketExceptionFactory+ExtendedSocketException: A connection attempt failed because the connected party did not properly respond after a period of time, or established connection failed because connected host has failed to respond 17.56.136.170:465
   at System.Runtime.ExceptionServices.ExceptionDispatchInfo.Throw()
   at System.Net.Sockets.Socket.EndConnect(IAsyncResult asyncResult)
   at System.Net.Sockets.Socket.DoMultipleAddressConnectCallback(Object result, MultipleAddressConnectAsyncResult context)
--- End of stack trace from previous location where exception was thrown ---
   at System.Runtime.ExceptionServices.ExceptionDispatchInfo.Throw()
   at System.Net.Sockets.Socket.DoMultipleAddressConnectCallback(Object result, MultipleAddressConnectAsyncResult context)
   at System.Net.Sockets.Socket.MultipleAddressConnectCallback(IAsyncResult result)
--- End of stack trace from previous location where exception was thrown ---
   at System.Runtime.ExceptionServices.ExceptionDispatchInfo.Throw()
   at System.Net.Sockets.Socket.EndConnect(IAsyncResult asyncResult)
   at System.Net.Sockets.TcpClient.EndConnect(IAsyncResult asyncResult)
   at System.Net.Mail.SmtpConnection.ConnectAndHandshakeAsyncResult.InitializeConnectionCallback(IAsyncResult result)
--- End of stack trace from previous location where exception was thrown ---
   at System.Runtime.ExceptionServices.ExceptionDispatchInfo.Throw()
   at System.Net.Mail.SmtpConnection.ConnectAndHandshakeAsyncResult.End(IAsyncResult result)
   at System.Net.Mail.SmtpTransport.EndGetConnection(IAsyncResult result)
   at System.Net.Mail.SmtpClient.ConnectCallback(IAsyncResult result)
   --- End of inner exception stack trace ---
   at System.Runtime.ExceptionServices.ExceptionDispatchInfo.Throw()
   at System.Runtime.CompilerServices.TaskAwaiter.HandleNonSuccessAndDebuggerNotification(Task task)
   at ElMaitre.Web.Helpers.EmailSender.<Send>d__2.MoveNext()
2019-09-16 19:32:21.6768 INFO Failed to send the mail
2019-09-16 19:32:21.7373 ERROR System.Net.Mail.SmtpException: Transaction failed. The server response was: 5.7.1 <unknown[41.235.69.61]>: Client host rejected: Access denied
   at System.Net.Mail.RecipientCommand.CheckResponse(SmtpStatusCode statusCode, String response)
   at System.Net.Mail.RecipientCommand.EndSend(IAsyncResult result, String& response)
   at System.Net.Mail.SendMailAsyncResult.SendToCollectionCompleted(IAsyncResult result)
--- End of stack trace from previous location where exception was thrown ---
   at System.Runtime.ExceptionServices.ExceptionDispatchInfo.Throw()
   at System.Net.Mail.SendMailAsyncResult.End(IAsyncResult result)
   at System.Net.Mail.SmtpClient.SendMailCallback(IAsyncResult result)
--- End of stack trace from previous location where exception was thrown ---
   at System.Runtime.ExceptionServices.ExceptionDispatchInfo.Throw()
   at System.Runtime.CompilerServices.TaskAwaiter.HandleNonSuccessAndDebuggerNotification(Task task)
   at ElMaitre.Web.Helpers.EmailSender.<Send>d__2.MoveNext()
2019-09-16 19:55:16.3404 INFO Failed to send the mail
2019-09-16 19:55:16.4182 ERROR System.Net.Mail.SmtpException: The SMTP server requires a secure connection or the client was not authenticated. The server response was: 5.5.1 Authentication Required. Learn more at
   at System.Net.Mail.MailCommand.CheckResponse(SmtpStatusCode statusCode, String response)
   at System.Net.Mail.MailCommand.EndSend(IAsyncResult result)
   at System.Net.Mail.SendMailAsyncResult.SendMailFromCompleted(IAsyncResult result)
--- End of stack trace from previous location where exception was thrown ---
   at System.Runtime.ExceptionServices.ExceptionDispatchInfo.Throw()
   at System.Net.Mail.SendMailAsyncResult.End(IAsyncResult result)
   at System.Net.Mail.SmtpClient.SendMailCallback(IAsyncResult result)
--- End of stack trace from previous location where exception was thrown ---
   at System.Runtime.ExceptionServices.ExceptionDispatchInfo.Throw()
   at System.Runtime.CompilerServices.TaskAwaiter.HandleNonSuccessAndDebuggerNotification(Task task)
   at ElMaitre.Web.Helpers.EmailSender.<Send>d__2.MoveNext() in F:\Freelance\Mohamy\ElMaitre.Web3\Helpers\EmailSender.cs:line 66
2019-09-16 23:36:12.8815 INFO Failed to send the mail
2019-09-16 23:36:12.9944 ERROR System.Net.Mail.SmtpException: The SMTP server requires a secure connection or the client was not authenticated. The server response was: 5.5.1 Authentication Required. Learn more at
   at System.Net.Mail.MailCommand.CheckResponse(SmtpStatusCode statusCode, String response)
   at System.Net.Mail.MailCommand.EndSend(IAsyncResult result)
   at System.Net.Mail.SendMailAsyncResult.SendMailFromCompleted(IAsyncResult result)
--- End of stack trace from previous location where exception was thrown ---
   at System.Runtime.ExceptionServices.ExceptionDispatchInfo.Throw()
   at System.Net.Mail.SendMailAsyncResult.End(IAsyncResult result)
   at System.Net.Mail.SmtpClient.SendMailCallback(IAsyncResult result)
--- End of stack trace from previous location where exception was thrown ---
   at System.Runtime.ExceptionServices.ExceptionDispatchInfo.Throw()
   at System.Runtime.CompilerServices.TaskAwaiter.HandleNonSuccessAndDebuggerNotification(Task task)
   at ElMaitre.Web.Helpers.EmailSender.<Send>d__2.MoveNext() in F:\Freelance\Mohamy\ElMaitre.Web3\Helpers\EmailSender.cs:line 63
2019-09-16 23:42:19.6767 INFO Failed to send the mail
2019-09-16 23:42:19.8237 ERROR System.Net.Mail.SmtpException: The SMTP server requires a secure connection or the client was not authenticated. The server response was: 5.5.1 Authentication Required. Learn more at
   at System.Net.Mail.MailCommand.CheckResponse(SmtpStatusCode statusCode, String response)
   at System.Net.Mail.MailCommand.EndSend(IAsyncResult result)
   at System.Net.Mail.SendMailAsyncResult.SendMailFromCompleted(IAsyncResult result)
--- End of stack trace from previous location where exception was thrown ---
   at System.Runtime.ExceptionServices.ExceptionDispatchInfo.Throw()
   at System.Net.Mail.SendMailAsyncResult.End(IAsyncResult result)
   at System.Net.Mail.SmtpClient.SendMailCallback(IAsyncResult result)
--- End of stack trace from previous location where exception was thrown ---
   at System.Runtime.ExceptionServices.ExceptionDispatchInfo.Throw()
   at System.Runtime.CompilerServices.TaskAwaiter.HandleNonSuccessAndDebuggerNotification(Task task)
   at ElMaitre.Web.Helpers.EmailSender.<Send>d__2.MoveNext() in F:\Freelance\Mohamy\ElMaitre.Web3\Helpers\EmailSender.cs:line 63
2019-09-16 23:46:28.1701 INFO Failed to send the mail
2019-09-16 23:46:28.2578 ERROR System.Net.Mail.SmtpException: The SMTP server requires a secure connection or the client was not authenticated. The server response was: 5.5.1 Authentication Required. Learn more at
   at System.Net.Mail.MailCommand.CheckResponse(SmtpStatusCode statusCode, String response)
   at System.Net.Mail.MailCommand.EndSend(IAsyncResult result)
   at System.Net.Mail.SendMailAsyncResult.SendMailFromCompleted(IAsyncResult result)
--- End of stack trace from previous location where exception was thrown ---
   at System.Runtime.ExceptionServices.ExceptionDispatchInfo.Throw()
   at System.Net.Mail.SendMailAsyncResult.End(IAsyncResult result)
   at System.Net.Mail.SmtpClient.SendMailCallback(IAsyncResult result)
--- End of stack trace from previous location where exception was thrown ---
   at System.Runtime.ExceptionServices.ExceptionDispatchInfo.Throw()
   at System.Runtime.CompilerServices.TaskAwaiter.HandleNonSuccessAndDebuggerNotification(Task task)
   at ElMaitre.Web.Helpers.EmailSender.<Send>d__2.MoveNext() in F:\Freelance\Mohamy\ElMaitre.Web3\Helpers\EmailSender.cs:line 63
2019-09-16 23:47:01.4367 INFO Failed to send the mail
2019-09-16 23:47:01.4968 ERROR System.Net.Mail.SmtpException: The SMTP server requires a secure connection or the client was not authenticated. The server response was: 5.5.1 Authentication Required. Learn more at
   at System.Net.Mail.MailCommand.CheckResponse(SmtpStatusCode statusCode, String response)
   at System.Net.Mail.MailCommand.EndSend(IAsyncResult result)
   at System.Net.Mail.SendMailAsyncResult.SendMailFromCompleted(IAsyncResult result)
--- End of stack trace from previous location where exception was thrown ---
   at System.Runtime.ExceptionServices.ExceptionDispatchInfo.Throw()
   at System.Net.Mail.SendMailAsyncResult.End(IAsyncResult result)
   at System.Net.Mail.SmtpClient.SendMailCallback(IAsyncResult result)
--- End of stack trace from previous location where exception was thrown ---
   at System.Runtime.ExceptionServices.ExceptionDispatchInfo.Throw()
   at System.Runtime.CompilerServices.TaskAwaiter.HandleNonSuccessAndDebuggerNotification(Task task)
   at ElMaitre.Web.Helpers.EmailSender.<Send>d__2.MoveNext() in F:\Freelance\Mohamy\ElMaitre.Web3\Helpers\EmailSender.cs:line 63
2019-09-16 23:47:49.6489 INFO Failed to send the mail
2019-09-16 23:47:49.7297 ERROR System.Net.Mail.SmtpException: The SMTP server requires a secure connection or the client was not authenticated. The server response was: 5.5.1 Authentication Required. Learn more at
   at System.Net.Mail.MailCommand.CheckResponse(SmtpStatusCode statusCode, String response)
   at System.Net.Mail.MailCommand.EndSend(IAsyncResult result)
   at System.Net.Mail.SendMailAsyncResult.SendMailFromCompleted(IAsyncResult result)
--- End of stack trace from previous location where exception was thrown ---
   at System.Runtime.ExceptionServices.ExceptionDispatchInfo.Throw()
   at System.Net.Mail.SendMailAsyncResult.End(IAsyncResult result)
   at System.Net.Mail.SmtpClient.SendMailCallback(IAsyncResult result)
--- End of stack trace from previous location where exception was thrown ---
   at System.Runtime.ExceptionServices.ExceptionDispatchInfo.Throw()
   at System.Runtime.CompilerServices.TaskAwaiter.HandleNonSuccessAndDebuggerNotification(Task task)
   at ElMaitre.Web.Helpers.EmailSender.<Send>d__2.MoveNext() in F:\Freelance\Mohamy\ElMaitre.Web3\Helpers\EmailSender.cs:line 63
2019-09-16 23:59:31.3123 INFO Failed to send the mail
2019-09-16 23:59:31.3999 ERROR System.Net.Mail.SmtpException: The SMTP server requires a secure connection or the client was not authenticated. The server response was: 5.5.1 Authentication Required. Learn more at
   at System.Net.Mail.MailCommand.CheckResponse(SmtpStatusCode statusCode, String response)
   at System.Net.Mail.MailCommand.EndSend(IAsyncResult result)
   at System.Net.Mail.SendMailAsyncResult.SendMailFromCompleted(IAsyncResult result)
--- End of stack trace from previous location where exception was thrown ---
   at System.Runtime.ExceptionServices.ExceptionDispatchInfo.Throw()
   at System.Net.Mail.SendMailAsyncResult.End(IAsyncResult result)
   at System.Net.Mail.SmtpClient.SendMailCallback(IAsyncResult result)
--- End of stack trace from previous location where exception was thrown ---
   at System.Runtime.ExceptionServices.ExceptionDispatchInfo.Throw()
   at System.Runtime.CompilerServices.TaskAwaiter.HandleNonSuccessAndDebuggerNotification(Task task)
   at ElMaitre.Web.Helpers.EmailSender.<Send>d__2.MoveNext()
